Workbook

Sheet Dashboard
D2: Akquise · Master-Sheet 2026
D3: Pipeline · Funnel · Umsatz · Zielplanung
B6: PIPELINE-ÜBERSICHT
B7: Akquise | C7: Quali-Calls | D7: Sales-Calls | E7: Kunden | F7: Conversion | G7: Offene Pipeline
B8: =COUNTA(Akquise[Firmenname]) -> 259 | C8: =COUNTA(QualliCalls[Firmenname]) -> 2 | D8: =COUNTA(SaleCalls[Firmenname]) -> 2 | E8: =COUNTA(Kunden[Firmenname]) -> 4 | F8: =IFERROR(E8/B8,0) -> 0.015444015 | G8: =SUMIF(SaleCalls[Sales-Ergebnis],"Offen",SaleCalls[Angebotsvolumen (€)])+SUMIF(SaleCalls[Sales-Ergebnis],"Follow-up",SaleCalls[Angebotsvolumen (€)]) -> 1750
B10: NACH ZIELGRUPPE
B11: Zielgruppe | C11: Akquise | D11: Quali-Calls | E11: Kunden | F11: Conversion | H11: GESAMT | I11: Akquise | J11: Quali-Calls | K11: Kunden | L11: Conversion
B12: =IFERROR(__xludf.DUMMYFUNCTION("QUERY(Dropdowns[Zielgruppe], ""SELECT *"", 1)"),"Coaches & Berater") -> Coaches & Berater | C12: =IF(B12="","",COUNTIF(Akquise[Zielgruppe],$B12)) -> 2 | D12: =IF(B12="","",COUNTIF(QualliCalls[Zielgruppe],$B12)) -> 0 | E12: =COUNTIF(Kunden!$B$4:$B$828,$B12) -> 1 | F12: =IFERROR(E12/C12,0) -> 0.5 | I12: =SUM(C12:C988) -> 259 | J12: =SUM(D12:D988) -> 2 | K12: =SUM(E12:E988) -> 2 | L12: =IFERROR(K12/I12,0) -> 0.0077220077
B13: =IFERROR(__xludf.DUMMYFUNCTION("""COMPUTED_VALUE"""),"Steuerberater & Anwälte") -> Steuerberater & Anwälte | C13: =IF(B13="","",COUNTIF(Akquise[Zielgruppe],$B13)) -> 251 | D13: =IF(B13="","",COUNTIF(QualliCalls[Zielgruppe],$B13)) -> 0 | E13: =COUNTIF(Kunden!$B$4:$B$828,$B13) -> 0 | F13: =IFERROR(E13/C13,0) -> 0
B14: =IFERROR(__xludf.DUMMYFUNCTION("""COMPUTED_VALUE"""),"Immobilien & Makler") -> Immobilien & Makler | C14: =IF(B14="","",COUNTIF(Akquise[Zielgruppe],$B14)) -> 3 | D14: =IF(B14="","",COUNTIF(QualliCalls[Zielgruppe],$B14)) -> 1 | E14: =COUNTIF(Kunden!$B$4:$B$828,$B14) -> 0 | F14: =IFERROR(E14/C14,0) -> 0
B15: =IFERROR(__xludf.DUMMYFUNCTION("""COMPUTED_VALUE"""),"Handwerk & Lokal") -> Handwerk & Lokal | C15: =IF(B15="","",COUNTIF(Akquise[Zielgruppe],$B15)) -> 0 | D15: =IF(B15="","",COUNTIF(QualliCalls[Zielgruppe],$B15)) -> 0 | E15: =COUNTIF(Kunden!$B$4:$B$828,$B15) -> 0 | F15: =IFERROR(E15/C15,0) -> 0 | I15: Leads starten in „Akquise". Bei Ergebnis „Qualifiziert" / „Abgeschlossen" rückt der Lead automatisch ins nächste Blatt (per Apps-Script). Alle Zahlen hier zählen live über die Phasen-Blätter.
B16: =IFERROR(__xludf.DUMMYFUNCTION("""COMPUTED_VALUE"""),"Musik & Event") -> Musik & Event | C16: =IF(B16="","",COUNTIF(Akquise[Zielgruppe],$B16)) -> 1 | D16: =IF(B16="","",COUNTIF(QualliCalls[Zielgruppe],$B16)) -> 1 | E16: =COUNTIF(Kunden!$B$4:$B$828,$B16) -> 1 | F16: =IFERROR(E16/C16,0) -> 1
B17: =IFERROR(__xludf.DUMMYFUNCTION("""COMPUTED_VALUE"""),"Agentur (Subcontracting)") -> Agentur (Subcontracting) | C17: =IF(B17="","",COUNTIF(Akquise[Zielgruppe],$B17)) -> 0 | D17: =IF(B17="","",COUNTIF(QualliCalls[Zielgruppe],$B17)) -> 0 | E17: =COUNTIF(Kunden!$B$4:$B$828,$B17) -> 0 | F17: =IFERROR(E17/C17,0) -> 0
B18: =IFERROR(__xludf.DUMMYFUNCTION("""COMPUTED_VALUE"""),"Sonstige") -> Sonstige | C18: =IF(B18="","",COUNTIF(Akquise[Zielgruppe],$B18)) -> 2 | D18: =IF(B18="","",COUNTIF(QualliCalls[Zielgruppe],$B18)) -> 0 | E18: =COUNTIF(Kunden!$B$4:$B$828,$B18) -> 0 | F18: =IFERROR(E18/C18,0) -> 0
C19: =IF(B19="","",COUNTIF(Akquise[Zielgruppe],$B19)) | D19: =IF(B19="","",COUNTIF(QualliCalls[Zielgruppe],$B19))
C20: =IF(B20="","",COUNTIF(Akquise[Zielgruppe],$B20)) | D20: =IF(B20="","",COUNTIF(QualliCalls[Zielgruppe],$B20))
C21: =IF(B21="","",COUNTIF(Akquise[Zielgruppe],$B21)) | D21: =IF(B21="","",COUNTIF(QualliCalls[Zielgruppe],$B21))
C22: =IF(B22="","",COUNTIF(Akquise[Zielgruppe],$B22)) | D22: =IF(B22="","",COUNTIF(QualliCalls[Zielgruppe],$B22))
C23: =IF(B23="","",COUNTIF(Akquise[Zielgruppe],$B23)) | D23: =IF(B23="","",COUNTIF(QualliCalls[Zielgruppe],$B23))
C24: =IF(B24="","",COUNTIF(Akquise[Zielgruppe],$B24)) | D24: =IF(B24="","",COUNTIF(QualliCalls[Zielgruppe],$B24))
C25: =IF(B25="","",COUNTIF(Akquise[Zielgruppe],$B25)) | D25: =IF(B25="","",COUNTIF(QualliCalls[Zielgruppe],$B25))
C26: =IF(B26="","",COUNTIF(Akquise[Zielgruppe],$B26)) | D26: =IF(B26="","",COUNTIF(QualliCalls[Zielgruppe],$B26))
C27: =IF(B27="","",COUNTIF(Akquise[Zielgruppe],$B27)) | D27: =IF(B27="","",COUNTIF(QualliCalls[Zielgruppe],$B27))
C28: =IF(B28="","",COUNTIF(Akquise[Zielgruppe],$B28)) | D28: =IF(B28="","",COUNTIF(QualliCalls[Zielgruppe],$B28))

Sheet Akquise
A1: ID | B1: Zielgruppe | C1: Firmenname | D1: Ansprechpartner | E1: Position | F1: Stadt / Region | G1: Website | H1: Telefon | I1: E-Mail | J1: Quelle | K1: Website-Qualität | L1: Priorität | M1: Erstkontakt am | N1: Akquise-Ergebnis | O1: Wiedervorlage | P1: Notizen
A2: =IF($C2<>"","L-"&TEXT(ROW()-1,"000"),"") -> L-001 | B2: Coaches & Berater | C2: Müller Partner - Personal- und Organisationsentwicklung | D2: Sonja Trieschmann | Eveline Siehler | Fabian Büser | E2: Partner | F2: Kassel | G2: https://www.muellerundpartner.de/was/coaching | H2: +49 561 93874 – 0 | I2: info@muellerundpartner.de | J2: KI | K2: Schlecht | L2: 🟡 Mittel | N2: Offen
A3: =IF($C3<>"","L-"&TEXT(ROW()-1,"000"),"") -> L-002 | B3: Coaches & Berater | C3: Coaching Dr. Keller | D3: Monika Keller | E3: Inhaberin | F3: Adendorf | G3: https://coaching-keller.de/persoenliches-coaching/ | H3: 01234/56789 | I3: kontakt@coaching-keller.de | J3: KI | K3: Sehr schlecht | L3: 🔴 Hoch | N3: Offen
A4: =IF($C4<>"","L-"&TEXT(ROW()-1,"000"),"") -> L-003 | B4: Steuerberater & Anwälte | C4: Kanzlei Hoffmann | D4: Magaret Hoffmann | E4: Geschäftsführerin | F4: Bremerhaven | G4: https://www.kanzlei-hoffmann.de/ | H4: 0172 – 5920020 | I4: kontakt@kanzlei-hoffmann.de | J4: KI | K4: Sehr schlecht | L4: 🔴 Hoch | N4: Offen
A5: =IF($C5<>"","L-"&TEXT(ROW()-1,"000"),"") -> L-004 | B5: Steuerberater & Anwälte | C5: Steenberg Rechtsanwälte | D5: Jan Gregor Steenberg | E5: Geschäftsführer | F5: Karlsruhe | G5: https://www.kanzlei-steenberg.de/ | H5: 07231 / 1331993-0 | I5: info@kanzlei-steenberg.de | J5: KI | K5: Schlecht | L5: 🔴 Hoch | N5: Offen
A6: =IF($C6<>"","L-"&TEXT(ROW()-1,"000"),"") -> L-005 | B6: Steuerberater & Anwälte | C6: Anwaltskanzlei Weber | D6: Wilhelm Alexander Weber | E6: Rechtsanwalt | F6: Sachsen | G6: https://anwalt-weber.de/ | H6: 0351-476 75 47 | I6: kanzlei@anwalt-weber.de | J6: KI | K6: Sehr schlecht | L6: 🔴 Hoch | N6: Offen
A7: =IF($C7<>"","L-"&TEXT(ROW()-1,"000"),"") -> L-006 | B7: Steuerberater & Anwälte | C7: Porkert Rechtsanwälte | D7: Sascha Porkert | E7: Rechtsanwalt | F7: Aschaffenburg | G7: http://www.porkert-rechtsanwaelte.de/ | H7: 0 60 21 - 438 77 - 60 | I7: info@PORKERT-Rechtsanwaelte.de | J7: Google | K7: Sehr schlecht | L7: 🟡 Mittel | N7: Offen | P7: Website nicht sicher
A8: =IF($C8<>"","L-"&TEXT(ROW()-1,"000"),"") -> L-007 | B8: Steuerberater & Anwälte | C8: Kaup + Goes | F8: Aschaffenburg | G8: https://www.kaupgoes.de/ | H8: 06021-581683 | I8: info@kaupgoes.de | J8: Google | K8: Schlecht | L8: 🟢 Niedrig | N8: Offen
A9: =IF($C9<>"","L-"&TEXT(ROW()-1,"000"),"") -> L-008 | B9: Steuerberater & Anwälte | C9: D.Waterstradt | D9: Diane Waterstradt | E9: Rechtsanwalt | F9: Aschaffenburg | G9: https://www.meineanwaeltin.de/ | H9: 06021 | 581650 | I9: DW@meineAnwaeltin.de | J9: Google | K9: Schlecht | L9: 🟢 Niedrig | N9: Offen
A10: =IF($C10<>"","L-"&TEXT(ROW()-1,"000"),"") -> L-009 | B10: Steuerberater & Anwälte | C10: Dr. Heinrich Fussbahn | D10: Robert Öhrlein | E10: Rechtsanwalt | F10: Aschaffenburg | G10: https://www.rechtsanwaelte-ab.de/ | H10: 06021-5826083 | I10: kanzlei-robert-oehrlein@web.de | J10: Google | K10: Ausbaufähig | L10: 🟢 Niedrig | N10: Offen
A11: =IF($C11<>"","L-"&TEXT(ROW()-1,"000"),"") -> L-010 | B11: Steuerberater & Anwälte | C11: Fuchs und Fuchs Rechtsanwälte | F11: Aschaffenburg | H11: 06021 362370 | J11: Google | K11: Keine Website | L11: 🔴 Hoch | N11: Offen | P11: Keine Website vorhanden
A12: =IF($C12<>"","L-"&TEXT(ROW()-1,"000"),"") -> L-011 | B12: Steuerberater & Anwälte | C12: Claudia Pfad | D12: Claudia Pfad | E12: Rechtsanwalt | F12: Aschaffenburg | G12: https://www.kanzlei-pfad.de/ | H12: 06021/423894 | I12: pfadkanzlei-pfad.de | J12: Google | K12: Schlecht | L12: 🟡 Mittel | N12: Offen
A13: =IF($C13<>"","L-"&TEXT(ROW()-1,"000"),"") -> L-012 | B13: Steuerberater & Anwälte | C13: Dirk Faust & Bernd Fronemann | D13: Dirk Faust | E13: Sozietät | F13: Aschaffenburg | G13: https://www.faust-rechtsanwalt.de/ | H13: 06021 - 44 88 7 0 | I13: info@faust-rechtsanwalt.de | J13: Google | K13: Ausbaufähig | L13: 🟢 Niedrig | N13: Offen
A14: =IF($C14<>"","L-"&TEXT(ROW()-1,"000"),"") -> L-013 | B14: Steuerberater & Anwälte | C14: Ohly Zöller | F14: Aschaffenburg | G14: https://rae-ohly-zoeller.com/ | H14: 06021/3868330 | I14: advokat@rae-ohly-zoeller.de | J14: Google | K14: Ausbaufähig | L14: 🟢 Niedrig | N14: Offen | P14: Sehr langsame Website, kein Impressum
A15: =IF($C15<>"","L-"&TEXT(ROW()-1,"000"),"") -> L-014 | B15: Steuerberater & Anwälte | C15: Rechtsanwalt Dirk Witteck | D15: Dirk Witteck | E15: Rechtsanwalt | F15: Großwallstadt | G15: https://www.rechtsanwalt-witteck.de/ | H15: 06022/2055-2240 | I15: post@rechtsanwalt-witteck.de | J15: Google | K15: Schlecht | L15: 🟢 Niedrig | N15: Offen
A16: =IF($C16<>"","L-"&TEXT(ROW()-1,"000"),"") -> L-015 | B16: Steuerberater & Anwälte | C16: Kade et kade | F16: Aschaffenburg | G16: https://kade-kade.de/ | H16: +49 (0) 60 21 / 150 680 | I16: raekade@kade-kade.de | J16: Google | K16: Ausbaufähig | L16: 🟢 Niedrig | N16: Offen
A17: =IF($C17<>"","L-"&TEXT(ROW()-1,"000"),"") -> L-016 | B17: Steuerberater & Anwälte | C17: Silke Mayerhöfer | F17: Aschaffenburg | H17: 06021 22752 | J17: Google | K17: Keine Website | L17: 🔴 Hoch | N17: Offen | P17: Keine Website vorhanden
A18: =IF($C18<>"","L-"&TEXT(ROW()-1,"000"),"") -> L-017 | B18: Steuerberater & Anwälte | C18: rae-aschaffenburg | F18: Aschaffenburg | G18: https://www.rae-aschaffenburg.de/?c=startseite | H18: 06021 / 4487747 | I18: info@rae-aschaffenburg.de | J18: Google | K18: Schlecht | L18: 🟡 Mittel | N18: Offen
A19: =IF($C19<>"","L-"&TEXT(ROW()-1,"000"),"") -> L-018 | B19: Steuerberater & Anwälte | C19: Bernhard & Neumeier Janßen | D19: Peter Bernhard/Udo Neumeier | E19: 06021-62552-10 | F19: Aschaffenburg | G19: https://www.kanzlei-bernhard-und-neumeier.de/%C3%BCber-die-kanzleien/udo-neumeier/ | H19: 06021-62552-10 | I19: kanzlei@rae-bnj.de | J19: Google | K19: Schlecht | L19: 🟡 Mittel | N19: Offen
A20: =IF($C20<>"","L-"&TEXT(ROW()-1,"000"),"") -> L-019 | B20: Steuerberater & Anwälte | C20: Anwalts Mediatorin | D20: Sabine Langhirt | E20: Meditatorin, Sozialtherapeutin, Fachanwältin für Familienrecht, Rechtsanwältin | F20: Aschaffenburg | G20: https://www.anwalts-mediatorin.de/ | H20: 06021 929004 | I20: mediation@langhirt.eu | J20: Google | K20: Sehr schlecht | L20: 🔴 Hoch | N20: Offen
A21: =IF($C21<>"","L-"&TEXT(ROW()-1,"000"),"") -> L-020 | B21: Steuerberater & Anwälte | C21: Anwalts Kanzlei Ziemer | D21: Monika Ziemer | E21: Fachanwältin für Miet- und Wohnungseigentumsrecht/Strafrecht | F21: Aschaffenburg | G21: https://www.az-kanzlei.de/ | H21: 06021 44 295 3 | I21: ziemer@az-kanzlei.de | J21: Google | K21: Schlecht | L21: 🟢 Niedrig | N21: Offen
A22: =IF($C22<>"","L-"&TEXT(ROW()-1,"000"),"") -> L-021 | B22: Steuerberater & Anwälte | C22: Rechtsanwalt Schwab | F22: Aschaffenburg | H22: 06021 35010 | J22: Google | K22: Keine Website | L22: 🔴 Hoch | N22: Offen | P22: Keine Website vorhanden
A23: =IF($C23<>"","L-"&TEXT(ROW()-1,"000"),"") -> L-022 | B23: Steuerberater & Anwälte | C23: Schaeffer Rechtsanwälte | F23: Aschaffenburg | H23: 06021 21678 | J23: Google | K23: Keine Website | L23: 🔴 Hoch | N23: Offen | P23: Keine Website vorhanden
A24: =IF($C24<>"","L-"&TEXT(ROW()-1,"000"),"") -> L-023 | B24: Steuerberater & Anwälte | C24: Rechtsanwalt-Stoklossa | F24: Aschaffenburg | H24: 06021 5851270 | J24: Google | K24: Keine Website | L24: 🔴 Hoch | N24: Offen | P24: Keine Website vorhanden
A25: =IF($C25<>"","L-"&TEXT(ROW()-1,"000"),"") -> L-024 | B25: Steuerberater & Anwälte | C25: Drik Jenny | D25: Dirk Jenny | E25: Rechtsanwalt | F25: Aschaffenburg | G25: https://www.anwalt-jenny.de/ | H25: 06021 30880 | I25: mail@anwalt-jenny.de | J25: Google | K25: Sehr schlecht | L25: 🔴 Hoch | N25: Offen
A26: =IF($C26<>"","L-"&TEXT(ROW()-1,"000"),"") -> L-025 | B26: Steuerberater & Anwälte | C26: Anwaltskanzlei Susanne Steigerwald | F26: Aschaffenburg | G26: https://www.anwaltskanzlei-ssa.de/ | H26: 06021 443670 | J26: Google | K26: Sehr schlecht | L26: 🔴 Hoch | N26: Offen | P26: Website führt Glückspiel Werbung?
A27: =IF($C27<>"","L-"&TEXT(ROW()-1,"000"),"") -> L-026 | B27: Steuerberater & Anwälte | C27: Rechtsanwältin Annette Reinheimer | D27: Anette Reinheimer | E27: Rechtsanwalt | F27: Aschaffenburg | G27: https://www.anwalt-reinheimer.de/ | H27: 06021 - 58 02 91 | I27: annette.reinheimer@t-online.de | J27: Google | K27: Schlecht | L27: 🟡 Mittel | N27: Offen
A28: =IF($C28<>"","L-"&TEXT(ROW()-1,"000"),"") -> L-027 | B28: Steuerberater & Anwälte | C28: Bach Rechtsanwälte Fachanwälte | D28: Günter Bach | E28: Geschäftsführer | F28: Aschaffenburg | G28: https://bach-anwaelte.de/ | H28: 06021 30880 | I28: info@bach-anwaelte.de | J28: Google | K28: Ausbaufähig | L28: 🟢 Niedrig | N28: Offen
A29: =IF($C29<>"","L-"&TEXT(ROW()-1,"000"),"") -> L-028 | B29: Steuerberater & Anwälte | C29: Rechtsanwälte LEEB & LEEB | D29: Hermann Leeb | E29: Rechtsanwalt | F29: Aschaffenburg | G29: https://www.rae-leeb.de/ | H29: 06021 - 21747 | I29: info@rakba.de | J29: Google | K29: Schlecht | L29: 🟢 Niedrig | N29: Offen
A30: =IF($C30<>"","L-"&TEXT(ROW()-1,"000"),"") -> L-029 | B30: Steuerberater & Anwälte | C30: Michael Volmer & Dr. Jens Neie | D30: Michael Volmer und Dr. Jens Neie | E30: Notare | F30: Aschaffenburg | G30: https://www.notaref15.de/formulare/kaufvertrag/ | H30: 06021 30 96 0 | I30: post@notaref15.de | J30: Google | K30: Ausbaufähig | L30: 🟢 Niedrig | N30: Offen | P30: Formulare
A31: =IF($C31<>"","L-"&TEXT(ROW()-1,"000"),"") -> L-030 | B31: Steuerberater & Anwälte | C31: Rechtsanwältin Eva Rombach | F31: Aschaffenburg | H31: 06021 9017400 | J31: Google | K31: Keine Website | L31: 🔴 Hoch | N31: Offen | P31: Keine Website vorhanden
A32: =IF($C32<>"","L-"&TEXT(ROW()-1,"000"),"") -> L-031 | B32: Steuerberater & Anwälte | C32: Rechtsanwalt Hans Peter Fink | F32: Aschaffenburg | H32: 06021 39950 | J32: Google | K32: Keine Website | L32: 🔴 Hoch | N32: Offen | P32: Keine Website vorhanden
A33: =IF($C33<>"","L-"&TEXT(ROW()-1,"000"),"") -> L-032 | B33: Steuerberater & Anwälte | C33: Beate von der Nahmer | F33: Aschaffenburg | H33: 06021 4599032 | J33: Google | K33: Keine Website | L33: 🔴 Hoch | N33: Offen | P33: Keine Website vorhanden
A34: =IF($C34<>"","L-"&TEXT(ROW()-1,"000"),"") -> L-033 | B34: Steuerberater & Anwälte | C34: Rechtsanwalt Klaus Lenzen | D34: Klaus Lenzen | E34: Rechtsanwalt | F34: Aschaffenburg | G34: https://www.rechtsanwalt-lenzen.de/ | H34: 06021 560 778 | I34: info@rechtsanwalt-lenzen.de | J34: Google | K34: Ausbaufähig | L34: 🟢 Niedrig | N34: Offen
A35: =IF($C35<>"","L-"&TEXT(ROW()-1,"000"),"") -> L-034 | B35: Steuerberater & Anwälte | C35: Dr. Koos & Kollegen | D35: Ulrich Koos | E35: Gesellschafter | F35: Aschaffenburg | G35: https://rae-koos.de/ | H35: 06021 3548-0 | I35: mail@rae-koos.de | J35: Google | K35: Ausbaufähig | L35: 🟢 Niedrig | N35: Offen
A36: =IF($C36<>"","L-"&TEXT(ROW()-1,"000"),"") -> L-035 | B36: Steuerberater & Anwälte | C36: Dr. Häcker & Kollegen | D36: Dr. Frank Häcker | E36: Rechtsanwalt | F36: Aschaffenburg | G36: https://www.drhaecker.de/ | H36: (06021) 454900 | I36: kanzlei@drhaecker.de | J36: Google | K36: Schlecht | L36: 🟡 Mittel | N36: Offen
A37: =IF($C37<>"","L-"&TEXT(ROW()-1,"000"),"") -> L-036 | B37: Steuerberater & Anwälte | C37: HAF Rechtsanwälte | F37: Aschaffenburg | H37: 06021 36890 | J37: Google | K37: Keine Website | L37: 🔴 Hoch | N37: Offen | P37: Keine Website vorhanden
A38: =IF($C38<>"","L-"&TEXT(ROW()-1,"000"),"") -> L-037 | B38: Steuerberater & Anwälte | C38: Rechtsanwalt Alexander Glück | D38: Alexander Glück | E38: Rechtsanwalt | F38: Aschaffenburg | G38: https://www.glueckalexander.de/ | H38: +49 (0)6021 4399632 | I38: info@alexanderglueck.de | J38: Google | K38: Schlecht | L38: 🟡 Mittel | N38: Offen
A39: =IF($C39<>"","L-"&TEXT(ROW()-1,"000"),"") -> L-038 | B39: Steuerberater & Anwälte | C39: Dr. Hufnagel | D39: Dr. Sven Hufnagel | E39: Rechtsanwalt | F39: Aschaffenburg | G39: https://www.anwalt-strafrecht.com/kontakt-fachanwalt-strafrecht-aschaffenburg | H39: (+49) 06021-21322 | I39: anwalt@dr-hufnagel.de | J39: Google | K39: Sehr schlecht | L39: 🟡 Mittel | N39: Offen
A40: =IF($C40<>"","L-"&TEXT(ROW()-1,"000"),"") -> L-039 | B40: Steuerberater & Anwälte | C40: Kanzlei Rath | D40: Johanna Rath | E40: Rechtsanwalt | F40: Aschaffenburg | G40: http://www.kanzleirath.de/ | H40: 0951/ 986.200 | I40: info@rakba.de | J40: Google | K40: Sehr schlecht | L40: 🔴 Hoch | N40: Offen | P40: Website nicht sicher
...

Sheet Akquise-Tracking
A1: Akquise-Tracking 2026
A2: Tägliche Kalt-Akquise Aktivitäten · Quoten werden automatisch berechnet
A3: Datum | B3: Wählversuche | C3: Gespräche mit Empfang | D3: Quote Empfang | E3: Gespräche mit Entscheider | F3: Quote Empfang Überwindung | G3: Termine vereinbart | H3: Quote Quali-Call
D4: =IFERROR(AkquiseTracking[[#This Row],[Wählversuche]]/AkquiseTracking[[#This Row],[Gespräche mit Empfang]],0) -> 0 | F4: =IFERROR(AkquiseTracking[[#This Row],[Gespräche mit Entscheider]]/AkquiseTracking[[#This Row],[Gespräche mit Empfang]],0) -> 0 | H4: =IFERROR(AkquiseTracking[[#This Row],[Termine vereinbart]]/AkquiseTracking[[#This Row],[Gespräche mit Empfang]],0) -> 0
D5: =IFERROR(AkquiseTracking[[#This Row],[Wählversuche]]/AkquiseTracking[[#This Row],[Gespräche mit Empfang]],0) -> 0 | F5: =IFERROR(AkquiseTracking[[#This Row],[Gespräche mit Entscheider]]/AkquiseTracking[[#This Row],[Gespräche mit Empfang]],0) -> 0 | H5: =IFERROR(AkquiseTracking[[#This Row],[Termine vereinbart]]/AkquiseTracking[[#This Row],[Gespräche mit Empfang]],0) -> 0 | J5: Kategorie | K5: ⌀ Schnitt
D6: =IFERROR(AkquiseTracking[[#This Row],[Wählversuche]]/AkquiseTracking[[#This Row],[Gespräche mit Empfang]],0) -> 0 | F6: =IFERROR(AkquiseTracking[[#This Row],[Gespräche mit Entscheider]]/AkquiseTracking[[#This Row],[Gespräche mit Empfang]],0) -> 0 | H6: =IFERROR(AkquiseTracking[[#This Row],[Termine vereinbart]]/AkquiseTracking[[#This Row],[Gespräche mit Empfang]],0) -> 0 | J6: Wählversuche | K6: =AVERAGE(AkquiseTracking[Wählversuche]) -> #DIV/0!
D7: =IFERROR(AkquiseTracking[[#This Row],[Wählversuche]]/AkquiseTracking[[#This Row],[Gespräche mit Empfang]],0) -> 0 | F7: =IFERROR(AkquiseTracking[[#This Row],[Gespräche mit Entscheider]]/AkquiseTracking[[#This Row],[Gespräche mit Empfang]],0) -> 0 | H7: =IFERROR(AkquiseTracking[[#This Row],[Termine vereinbart]]/AkquiseTracking[[#This Row],[Gespräche mit Empfang]],0) -> 0 | J7: Gespräch mit Empfang | K7: =AVERAGE(AkquiseTracking[Gespräche mit Empfang]) -> #DIV/0!
D8: =IFERROR(AkquiseTracking[[#This Row],[Wählversuche]]/AkquiseTracking[[#This Row],[Gespräche mit Empfang]],0) -> 0 | F8: =IFERROR(AkquiseTracking[[#This Row],[Gespräche mit Entscheider]]/AkquiseTracking[[#This Row],[Gespräche mit Empfang]],0) -> 0 | H8: =IFERROR(AkquiseTracking[[#This Row],[Termine vereinbart]]/AkquiseTracking[[#This Row],[Gespräche mit Empfang]],0) -> 0 | J8: Quote Empfang | K8: =AVERAGE(AkquiseTracking[Quote Empfang]) -> 0
D9: =IFERROR(AkquiseTracking[[#This Row],[Wählversuche]]/AkquiseTracking[[#This Row],[Gespräche mit Empfang]],0) -> 0 | F9: =IFERROR(AkquiseTracking[[#This Row],[Gespräche mit Entscheider]]/AkquiseTracking[[#This Row],[Gespräche mit Empfang]],0) -> 0 | H9: =IFERROR(AkquiseTracking[[#This Row],[Termine vereinbart]]/AkquiseTracking[[#This Row],[Gespräche mit Empfang]],0) -> 0 | J9: Gespräche mit Entscheider | K9: =AVERAGE(AkquiseTracking[Gespräche mit Entscheider]) -> #DIV/0!
D10: =IFERROR(AkquiseTracking[[#This Row],[Wählversuche]]/AkquiseTracking[[#This Row],[Gespräche mit Empfang]],0) -> 0 | F10: =IFERROR(AkquiseTracking[[#This Row],[Gespräche mit Entscheider]]/AkquiseTracking[[#This Row],[Gespräche mit Empfang]],0) -> 0 | H10: =IFERROR(AkquiseTracking[[#This Row],[Termine vereinbart]]/AkquiseTracking[[#This Row],[Gespräche mit Empfang]],0) -> 0 | J10: Quote Empfang Überwindung | K10: =AVERAGE(AkquiseTracking[Quote Empfang Überwindung]) -> 0
D11: =IFERROR(AkquiseTracking[[#This Row],[Wählversuche]]/AkquiseTracking[[#This Row],[Gespräche mit Empfang]],0) -> 0 | F11: =IFERROR(AkquiseTracking[[#This Row],[Gespräche mit Entscheider]]/AkquiseTracking[[#This Row],[Gespräche mit Empfang]],0) -> 0 | H11: =IFERROR(AkquiseTracking[[#This Row],[Termine vereinbart]]/AkquiseTracking[[#This Row],[Gespräche mit Empfang]],0) -> 0 | J11: Termine vereinbart | K11: =AVERAGE(AkquiseTracking[Termine vereinbart]) -> #DIV/0!
D12: =IFERROR(AkquiseTracking[[#This Row],[Wählversuche]]/AkquiseTracking[[#This Row],[Gespräche mit Empfang]],0) -> 0 | F12: =IFERROR(AkquiseTracking[[#This Row],[Gespräche mit Entscheider]]/AkquiseTracking[[#This Row],[Gespräche mit Empfang]],0) -> 0 | H12: =IFERROR(AkquiseTracking[[#This Row],[Termine vereinbart]]/AkquiseTracking[[#This Row],[Gespräche mit Empfang]],0) -> 0 | J12: Quote Quali-Call | K12: =AVERAGE(AkquiseTracking[Quote Quali-Call]) -> 0
D13: =IFERROR(AkquiseTracking[[#This Row],[Wählversuche]]/AkquiseTracking[[#This Row],[Gespräche mit Empfang]],0) -> 0 | F13: =IFERROR(AkquiseTracking[[#This Row],[Gespräche mit Entscheider]]/AkquiseTracking[[#This Row],[Gespräche mit Empfang]],0) -> 0 | H13: =IFERROR(AkquiseTracking[[#This Row],[Termine vereinbart]]/AkquiseTracking[[#This Row],[Gespräche mit Empfang]],0) -> 0
D14: =IFERROR(AkquiseTracking[[#This Row],[Wählversuche]]/AkquiseTracking[[#This Row],[Gespräche mit Empfang]],0) -> 0 | F14: =IFERROR(AkquiseTracking[[#This Row],[Gespräche mit Entscheider]]/AkquiseTracking[[#This Row],[Gespräche mit Empfang]],0) -> 0 | H14: =IFERROR(AkquiseTracking[[#This Row],[Termine vereinbart]]/AkquiseTracking[[#This Row],[Gespräche mit Empfang]],0) -> 0
D15: =IFERROR(AkquiseTracking[[#This Row],[Wählversuche]]/AkquiseTracking[[#This Row],[Gespräche mit Empfang]],0) -> 0 | F15: =IFERROR(AkquiseTracking[[#This Row],[Gespräche mit Entscheider]]/AkquiseTracking[[#This Row],[Gespräche mit Empfang]],0) -> 0 | H15: =IFERROR(AkquiseTracking[[#This Row],[Termine vereinbart]]/AkquiseTracking[[#This Row],[Gespräche mit Empfang]],0) -> 0
D16: =IFERROR(AkquiseTracking[[#This Row],[Wählversuche]]/AkquiseTracking[[#This Row],[Gespräche mit Empfang]],0) -> 0 | F16: =IFERROR(AkquiseTracking[[#This Row],[Gespräche mit Entscheider]]/AkquiseTracking[[#This Row],[Gespräche mit Empfang]],0) -> 0 | H16: =IFERROR(AkquiseTracking[[#This Row],[Termine vereinbart]]/AkquiseTracking[[#This Row],[Gespräche mit Empfang]],0) -> 0
D17: =IFERROR(AkquiseTracking[[#This Row],[Wählversuche]]/AkquiseTracking[[#This Row],[Gespräche mit Empfang]],0) -> 0 | F17: =IFERROR(AkquiseTracking[[#This Row],[Gespräche mit Entscheider]]/AkquiseTracking[[#This Row],[Gespräche mit Empfang]],0) -> 0 | H17: =IFERROR(AkquiseTracking[[#This Row],[Termine vereinbart]]/AkquiseTracking[[#This Row],[Gespräche mit Empfang]],0) -> 0
D18: =IFERROR(AkquiseTracking[[#This Row],[Wählversuche]]/AkquiseTracking[[#This Row],[Gespräche mit Empfang]],0) -> 0 | F18: =IFERROR(AkquiseTracking[[#This Row],[Gespräche mit Entscheider]]/AkquiseTracking[[#This Row],[Gespräche mit Empfang]],0) -> 0 | H18: =IFERROR(AkquiseTracking[[#This Row],[Termine vereinbart]]/AkquiseTracking[[#This Row],[Gespräche mit Empfang]],0) -> 0
D19: =IFERROR(AkquiseTracking[[#This Row],[Wählversuche]]/AkquiseTracking[[#This Row],[Gespräche mit Empfang]],0) -> 0 | F19: =IFERROR(AkquiseTracking[[#This Row],[Gespräche mit Entscheider]]/AkquiseTracking[[#This Row],[Gespräche mit Empfang]],0) -> 0 | H19: =IFERROR(AkquiseTracking[[#This Row],[Termine vereinbart]]/AkquiseTracking[[#This Row],[Gespräche mit Empfang]],0) -> 0
D20: =IFERROR(AkquiseTracking[[#This Row],[Wählversuche]]/AkquiseTracking[[#This Row],[Gespräche mit Empfang]],0) -> 0 | F20: =IFERROR(AkquiseTracking[[#This Row],[Gespräche mit Entscheider]]/AkquiseTracking[[#This Row],[Gespräche mit Empfang]],0) -> 0 | H20: =IFERROR(AkquiseTracking[[#This Row],[Termine vereinbart]]/AkquiseTracking[[#This Row],[Gespräche mit Empfang]],0) -> 0
D21: =IFERROR(AkquiseTracking[[#This Row],[Wählversuche]]/AkquiseTracking[[#This Row],[Gespräche mit Empfang]],0) -> 0 | F21: =IFERROR(AkquiseTracking[[#This Row],[Gespräche mit Entscheider]]/AkquiseTracking[[#This Row],[Gespräche mit Empfang]],0) -> 0 | H21: =IFERROR(AkquiseTracking[[#This Row],[Termine vereinbart]]/AkquiseTracking[[#This Row],[Gespräche mit Empfang]],0) -> 0
D22: =IFERROR(AkquiseTracking[[#This Row],[Wählversuche]]/AkquiseTracking[[#This Row],[Gespräche mit Empfang]],0) -> 0 | F22: =IFERROR(AkquiseTracking[[#This Row],[Gespräche mit Entscheider]]/AkquiseTracking[[#This Row],[Gespräche mit Empfang]],0) -> 0 | H22: =IFERROR(AkquiseTracking[[#This Row],[Termine vereinbart]]/AkquiseTracking[[#This Row],[Gespräche mit Empfang]],0) -> 0
D23: =IFERROR(AkquiseTracking[[#This Row],[Wählversuche]]/AkquiseTracking[[#This Row],[Gespräche mit Empfang]],0) -> 0 | F23: =IFERROR(AkquiseTracking[[#This Row],[Gespräche mit Entscheider]]/AkquiseTracking[[#This Row],[Gespräche mit Empfang]],0) -> 0 | H23: =IFERROR(AkquiseTracking[[#This Row],[Termine vereinbart]]/AkquiseTracking[[#This Row],[Gespräche mit Empfang]],0) -> 0
D24: =IFERROR(AkquiseTracking[[#This Row],[Wählversuche]]/AkquiseTracking[[#This Row],[Gespräche mit Empfang]],0) -> 0 | F24: =IFERROR(AkquiseTracking[[#This Row],[Gespräche mit Entscheider]]/AkquiseTracking[[#This Row],[Gespräche mit Empfang]],0) -> 0 | H24: =IFERROR(AkquiseTracking[[#This Row],[Termine vereinbart]]/AkquiseTracking[[#This Row],[Gespräche mit Empfang]],0) -> 0
... D500: =IFERROR(AkquiseTracking[[#This Row],[Wählversuche]]/AkquiseTracking[[#This Row],[Gespräche mit Empfang]],0) -> 0 | F500: =IFERROR(AkquiseTracking[[#This Row],[Gespräche mit Entscheider]]/AkquiseTracking[[#This Row],[Gespräche mit Empfang]],0) -> 0 | H500: =IFERROR(AkquiseTracking[[#This Row],[Termine vereinbart]]/AkquiseTracking[[#This Row],[Gespräche mit Empfang]],0) -> 0

Sheet Quali-Calls
A1: ID | B1: Zielgruppe | C1: Firmenname | D1: Ansprechpartner | E1: Telefon | F1: E-Mail | G1: Quali-Call am | H1: Quali-Ergebnis | I1: Wiedervorlage | J1: Bedarf / Notizen
A2: L-047 | B2: Musik & Event | C2: VMP Künstlerpool | D2: Bobby Stöcker | E2: 1775719570 | F2: info@v-m-p.com | G2: 46160 | H2: Qualifiziert
A3: L-113 | B3: Immobilien & Makler | C3: Privatperson | D3: Patick Badowski | E3: 01721409933 | F3: PatrickBadowski@web.de | G3: 46196 | H3: Qualifiziert

Sheet Sales-Calls
A1: ID | B1: Zielgruppe | C1: Firmenname | D1: Ansprechpartner | E1: Telefon | F1: E-Mail | G1: Closing-Call am | H1: Leistungen | I1: Angebotsvolumen (€) | J1: Leistungsbeginn | K1: Sales-Ergebnis | L1: Notizen
A2: L-047 | B2: Musik & Event | C2: VMP Künstlerpool | D2: Bobby Stöcker | E2: 1775719570 | F2: info@v-m-p.com | G2: 46162 | H2: Website Überarbeitung, SEO Grundlagen, Admin Bereich, ...(Siehe Angebot) | I2: 1300 | J2: 46174 | K2: Abgeschlossen
A3: L-113 | B3: Immobilien & Makler | C3: Privatperson | D3: Patick Badowski | E3: 01721409933 | F3: PatrickBadowski@web.de | H3: Erstellung eines profesionellen Online-Auftritts für seine Wohnung. Inklusive automatisiertem Kalender mit Kontaktanfrage | I3: 1750 | K3: Offen

Sheet Kunden
A1: ID | B1: Zielgruppe | C1: Firmenname | D1: Ansprechpartner | E1: Telefon | F1: E-Mail | G1: Leistungen | H1: Auftragsvolumen (€) | I1: Leistungsbeginn | J1: Abschluss am | K1: KD-NR | L1: Notizen
A2: - | B2: Musik & Event | C2: Threefliesbar | D2: Malik Semmler-Lins | E2: 015168106288 | K2: =IF($D2<>"","KD-"&TEXT(ROW()-1,"000"),"") -> KD-001
A3: - | B3: Musik & Event | C3: Bendixofficial | D3: Benjamin Engel | E3: 01749710557 | K3: =IF($D3<>"","KD-"&TEXT(ROW()-1,"000"),"") -> KD-002
A4: L-047 | B4: Musik & Event | C4: VMP Künstlerpool | D4: Bobby Stöcker | E4: 1775719570 | F4: info@v-m-p.com | G4: Website Überarbeitung, SEO Grundlagen, Admin Bereich, ...(Siehe Angebot) | H4: 1300 | I4: 46174 | J4: 46178 | K4: =IF($D4<>"","KD-"&TEXT(ROW()-1,"000"),"") -> KD-003
A5: - | B5: Coaches & Berater | C5: Bazooka City/Safe Untermain | D5: Sven Zöller | E5: 015119608040 | K5: =IF($D5<>"","KD-"&TEXT(ROW()-1,"000"),"") -> KD-004
K6: =IF($D6<>"","KD-"&TEXT(ROW()-1,"000"),"")
K7: =IF($D7<>"","KD-"&TEXT(ROW()-1,"000"),"")
K8: =IF($D8<>"","KD-"&TEXT(ROW()-1,"000"),"")
K9: =IF($D9<>"","KD-"&TEXT(ROW()-1,"000"),"")
K10: =IF($D10<>"","KD-"&TEXT(ROW()-1,"000"),"")
K11: =IF($D11<>"","KD-"&TEXT(ROW()-1,"000"),"")
K12: =IF($D12<>"","KD-"&TEXT(ROW()-1,"000"),"")

Sheet Funnel & Quoten
A1: [Schuck] Webdesign · Funnel & Quoten 2026
D2: Auswertungsjahr: | F2: 2026
A3: Monat | B3: Erstkontakte | C3: → Qualifiziert | D3: Akquise-Quote | E3: Quali-Calls | F3: → qualifiziert | G3: Quali-Quote | H3: Sales-Calls | I3: → Abschluss | J3: Abschluss-Quote
A4: =DATE($F$2,1,1) -> 46023 | B4: =COUNTIFS(Akquise[Erstkontakt am],">="&$A4,Akquise[Erstkontakt am],"<"&EDATE($A4,1)) -> 0 | C4: =COUNTIFS(Akquise[Erstkontakt am],">="&$A4,Akquise[Erstkontakt am],"<"&EDATE($A4,1),Akquise[Akquise-Ergebnis],"Qualifiziert") -> 0 | D4: =IFERROR(C4/B4,"") | E4: =COUNTIFS(QualliCalls[Quali-Call am],">="&$A4,QualliCalls[Quali-Call am],"<"&EDATE($A4,1)) -> 0 | F4: =COUNTIFS(QualliCalls[Quali-Call am],">="&$A4,QualliCalls[Quali-Call am],"<"&EDATE($A4,1),QualliCalls[Quali-Ergebnis],"Qualifiziert") -> 0 | G4: =IFERROR(F4/E4,"") | H4: =COUNTIFS(SaleCalls[Closing-Call am],">="&$A4,SaleCalls[Closing-Call am],"<"&EDATE($A4,1)) -> 0 | I4: =COUNTIFS(SaleCalls[Closing-Call am],">="&$A4,SaleCalls[Closing-Call am],"<"&EDATE($A4,1),SaleCalls[Sales-Ergebnis],"Abgeschlossen") -> 0 | J4: =IFERROR(I4/H4,"")
A5: =DATE($F$2,2,1) -> 46054 | B5: =COUNTIFS(Akquise[Erstkontakt am],">="&$A5,Akquise[Erstkontakt am],"<"&EDATE($A5,1)) -> 0 | C5: =COUNTIFS(Akquise[Erstkontakt am],">="&$A5,Akquise[Erstkontakt am],"<"&EDATE($A5,1),Akquise[Akquise-Ergebnis],"Qualifiziert") -> 0 | D5: =IFERROR(C5/B5,"") | E5: =COUNTIFS(QualliCalls[Quali-Call am],">="&$A5,QualliCalls[Quali-Call am],"<"&EDATE($A5,1)) -> 0 | F5: =COUNTIFS(QualliCalls[Quali-Call am],">="&$A5,QualliCalls[Quali-Call am],"<"&EDATE($A5,1),QualliCalls[Quali-Ergebnis],"Qualifiziert") -> 0 | G5: =IFERROR(F5/E5,"") | H5: =COUNTIFS(SaleCalls[Closing-Call am],">="&$A5,SaleCalls[Closing-Call am],"<"&EDATE($A5,1)) -> 0 | I5: =COUNTIFS(SaleCalls[Closing-Call am],">="&$A5,SaleCalls[Closing-Call am],"<"&EDATE($A5,1),SaleCalls[Sales-Ergebnis],"Abgeschlossen") -> 0 | J5: =IFERROR(I5/H5,"")
A6: =DATE($F$2,3,1) -> 46082 | B6: =COUNTIFS(Akquise[Erstkontakt am],">="&$A6,Akquise[Erstkontakt am],"<"&EDATE($A6,1)) -> 0 | C6: =COUNTIFS(Akquise[Erstkontakt am],">="&$A6,Akquise[Erstkontakt am],"<"&EDATE($A6,1),Akquise[Akquise-Ergebnis],"Qualifiziert") -> 0 | D6: =IFERROR(C6/B6,"") | E6: =COUNTIFS(QualliCalls[Quali-Call am],">="&$A6,QualliCalls[Quali-Call am],"<"&EDATE($A6,1)) -> 0 | F6: =COUNTIFS(QualliCalls[Quali-Call am],">="&$A6,QualliCalls[Quali-Call am],"<"&EDATE($A6,1),QualliCalls[Quali-Ergebnis],"Qualifiziert") -> 0 | G6: =IFERROR(F6/E6,"") | H6: =COUNTIFS(SaleCalls[Closing-Call am],">="&$A6,SaleCalls[Closing-Call am],"<"&EDATE($A6,1)) -> 0 | I6: =COUNTIFS(SaleCalls[Closing-Call am],">="&$A6,SaleCalls[Closing-Call am],"<"&EDATE($A6,1),SaleCalls[Sales-Ergebnis],"Abgeschlossen") -> 0 | J6: =IFERROR(I6/H6,"")
A7: =DATE($F$2,4,1) -> 46113 | B7: =COUNTIFS(Akquise[Erstkontakt am],">="&$A7,Akquise[Erstkontakt am],"<"&EDATE($A7,1)) -> 0 | C7: =COUNTIFS(Akquise[Erstkontakt am],">="&$A7,Akquise[Erstkontakt am],"<"&EDATE($A7,1),Akquise[Akquise-Ergebnis],"Qualifiziert") -> 0 | D7: =IFERROR(C7/B7,"") | E7: =COUNTIFS(QualliCalls[Quali-Call am],">="&$A7,QualliCalls[Quali-Call am],"<"&EDATE($A7,1)) -> 0 | F7: =COUNTIFS(QualliCalls[Quali-Call am],">="&$A7,QualliCalls[Quali-Call am],"<"&EDATE($A7,1),QualliCalls[Quali-Ergebnis],"Qualifiziert") -> 0 | G7: =IFERROR(F7/E7,"") | H7: =COUNTIFS(SaleCalls[Closing-Call am],">="&$A7,SaleCalls[Closing-Call am],"<"&EDATE($A7,1)) -> 0 | I7: =COUNTIFS(SaleCalls[Closing-Call am],">="&$A7,SaleCalls[Closing-Call am],"<"&EDATE($A7,1),SaleCalls[Sales-Ergebnis],"Abgeschlossen") -> 0 | J7: =IFERROR(I7/H7,"")
A8: =DATE($F$2,5,1) -> 46143 | B8: =COUNTIFS(Akquise[Erstkontakt am],">="&$A8,Akquise[Erstkontakt am],"<"&EDATE($A8,1)) -> 1 | C8: =COUNTIFS(Akquise[Erstkontakt am],">="&$A8,Akquise[Erstkontakt am],"<"&EDATE($A8,1),Akquise[Akquise-Ergebnis],"Qualifiziert") -> 1 | D8: =IFERROR(C8/B8,"") -> 1 | E8: =COUNTIFS(QualliCalls[Quali-Call am],">="&$A8,QualliCalls[Quali-Call am],"<"&EDATE($A8,1)) -> 1 | F8: =COUNTIFS(QualliCalls[Quali-Call am],">="&$A8,QualliCalls[Quali-Call am],"<"&EDATE($A8,1),QualliCalls[Quali-Ergebnis],"Qualifiziert") -> 1 | G8: =IFERROR(F8/E8,"") -> 1 | H8: =COUNTIFS(SaleCalls[Closing-Call am],">="&$A8,SaleCalls[Closing-Call am],"<"&EDATE($A8,1)) -> 1 | I8: =COUNTIFS(SaleCalls[Closing-Call am],">="&$A8,SaleCalls[Closing-Call am],"<"&EDATE($A8,1),SaleCalls[Sales-Ergebnis],"Abgeschlossen") -> 1 | J8: =IFERROR(I8/H8,"") -> 1
A9: =DATE($F$2,6,1) -> 46174 | B9: =COUNTIFS(Akquise[Erstkontakt am],">="&$A9,Akquise[Erstkontakt am],"<"&EDATE($A9,1)) -> 1 | C9: =COUNTIFS(Akquise[Erstkontakt am],">="&$A9,Akquise[Erstkontakt am],"<"&EDATE($A9,1),Akquise[Akquise-Ergebnis],"Qualifiziert") -> 1 | D9: =IFERROR(C9/B9,"") -> 1 | E9: =COUNTIFS(QualliCalls[Quali-Call am],">="&$A9,QualliCalls[Quali-Call am],"<"&EDATE($A9,1)) -> 1 | F9: =COUNTIFS(QualliCalls[Quali-Call am],">="&$A9,QualliCalls[Quali-Call am],"<"&EDATE($A9,1),QualliCalls[Quali-Ergebnis],"Qualifiziert") -> 1 | G9: =IFERROR(F9/E9,"") -> 1 | H9: =COUNTIFS(SaleCalls[Closing-Call am],">="&$A9,SaleCalls[Closing-Call am],"<"&EDATE($A9,1)) -> 0 | I9: =COUNTIFS(SaleCalls[Closing-Call am],">="&$A9,SaleCalls[Closing-Call am],"<"&EDATE($A9,1),SaleCalls[Sales-Ergebnis],"Abgeschlossen") -> 0 | J9: =IFERROR(I9/H9,"")
A10: =DATE($F$2,7,1) -> 46204 | B10: =COUNTIFS(Akquise[Erstkontakt am],">="&$A10,Akquise[Erstkontakt am],"<"&EDATE($A10,1)) -> 0 | C10: =COUNTIFS(Akquise[Erstkontakt am],">="&$A10,Akquise[Erstkontakt am],"<"&EDATE($A10,1),Akquise[Akquise-Ergebnis],"Qualifiziert") -> 0 | D10: =IFERROR(C10/B10,"") | E10: =COUNTIFS(QualliCalls[Quali-Call am],">="&$A10,QualliCalls[Quali-Call am],"<"&EDATE($A10,1)) -> 0 | F10: =COUNTIFS(QualliCalls[Quali-Call am],">="&$A10,QualliCalls[Quali-Call am],"<"&EDATE($A10,1),QualliCalls[Quali-Ergebnis],"Qualifiziert") -> 0 | G10: =IFERROR(F10/E10,"") | H10: =COUNTIFS(SaleCalls[Closing-Call am],">="&$A10,SaleCalls[Closing-Call am],"<"&EDATE($A10,1)) -> 0 | I10: =COUNTIFS(SaleCalls[Closing-Call am],">="&$A10,SaleCalls[Closing-Call am],"<"&EDATE($A10,1),SaleCalls[Sales-Ergebnis],"Abgeschlossen") -> 0 | J10: =IFERROR(I10/H10,"")
A11: =DATE($F$2,8,1) -> 46235 | B11: =COUNTIFS(Akquise[Erstkontakt am],">="&$A11,Akquise[Erstkontakt am],"<"&EDATE($A11,1)) -> 0 | C11: =COUNTIFS(Akquise[Erstkontakt am],">="&$A11,Akquise[Erstkontakt am],"<"&EDATE($A11,1),Akquise[Akquise-Ergebnis],"Qualifiziert") -> 0 | D11: =IFERROR(C11/B11,"") | E11: =COUNTIFS(QualliCalls[Quali-Call am],">="&$A11,QualliCalls[Quali-Call am],"<"&EDATE($A11,1)) -> 0 | F11: =COUNTIFS(QualliCalls[Quali-Call am],">="&$A11,QualliCalls[Quali-Call am],"<"&EDATE($A11,1),QualliCalls[Quali-Ergebnis],"Qualifiziert") -> 0 | G11: =IFERROR(F11/E11,"") | H11: =COUNTIFS(SaleCalls[Closing-Call am],">="&$A11,SaleCalls[Closing-Call am],"<"&EDATE($A11,1)) -> 0 | I11: =COUNTIFS(SaleCalls[Closing-Call am],">="&$A11,SaleCalls[Closing-Call am],"<"&EDATE($A11,1),SaleCalls[Sales-Ergebnis],"Abgeschlossen") -> 0 | J11: =IFERROR(I11/H11,"")
A12: =DATE($F$2,9,1) -> 46266 | B12: =COUNTIFS(Akquise[Erstkontakt am],">="&$A12,Akquise[Erstkontakt am],"<"&EDATE($A12,1)) -> 0 | C12: =COUNTIFS(Akquise[Erstkontakt am],">="&$A12,Akquise[Erstkontakt am],"<"&EDATE($A12,1),Akquise[Akquise-Ergebnis],"Qualifiziert") -> 0 | D12: =IFERROR(C12/B12,"") | E12: =COUNTIFS(QualliCalls[Quali-Call am],">="&$A12,QualliCalls[Quali-Call am],"<"&EDATE($A12,1)) -> 0 | F12: =COUNTIFS(QualliCalls[Quali-Call am],">="&$A12,QualliCalls[Quali-Call am],"<"&EDATE($A12,1),QualliCalls[Quali-Ergebnis],"Qualifiziert") -> 0 | G12: =IFERROR(F12/E12,"") | H12: =COUNTIFS(SaleCalls[Closing-Call am],">="&$A12,SaleCalls[Closing-Call am],"<"&EDATE($A12,1)) -> 0 | I12: =COUNTIFS(SaleCalls[Closing-Call am],">="&$A12,SaleCalls[Closing-Call am],"<"&EDATE($A12,1),SaleCalls[Sales-Ergebnis],"Abgeschlossen") -> 0 | J12: =IFERROR(I12/H12,"")
A13: =DATE($F$2,10,1) -> 46296 | B13: =COUNTIFS(Akquise[Erstkontakt am],">="&$A13,Akquise[Erstkontakt am],"<"&EDATE($A13,1)) -> 0 | C13: =COUNTIFS(Akquise[Erstkontakt am],">="&$A13,Akquise[Erstkontakt am],"<"&EDATE($A13,1),Akquise[Akquise-Ergebnis],"Qualifiziert") -> 0 | D13: =IFERROR(C13/B13,"") | E13: =COUNTIFS(QualliCalls[Quali-Call am],">="&$A13,QualliCalls[Quali-Call am],"<"&EDATE($A13,1)) -> 0 | F13: =COUNTIFS(QualliCalls[Quali-Call am],">="&$A13,QualliCalls[Quali-Call am],"<"&EDATE($A13,1),QualliCalls[Quali-Ergebnis],"Qualifiziert") -> 0 | G13: =IFERROR(F13/E13,"") | H13: =COUNTIFS(SaleCalls[Closing-Call am],">="&$A13,SaleCalls[Closing-Call am],"<"&EDATE($A13,1)) -> 0 | I13: =COUNTIFS(SaleCalls[Closing-Call am],">="&$A13,SaleCalls[Closing-Call am],"<"&EDATE($A13,1),SaleCalls[Sales-Ergebnis],"Abgeschlossen") -> 0 | J13: =IFERROR(I13/H13,"")
A14: =DATE($F$2,11,1) -> 46327 | B14: =COUNTIFS(Akquise[Erstkontakt am],">="&$A14,Akquise[Erstkontakt am],"<"&EDATE($A14,1)) -> 0 | C14: =COUNTIFS(Akquise[Erstkontakt am],">="&$A14,Akquise[Erstkontakt am],"<"&EDATE($A14,1),Akquise[Akquise-Ergebnis],"Qualifiziert") -> 0 | D14: =IFERROR(C14/B14,"") | E14: =COUNTIFS(QualliCalls[Quali-Call am],">="&$A14,QualliCalls[Quali-Call am],"<"&EDATE($A14,1)) -> 0 | F14: =COUNTIFS(QualliCalls[Quali-Call am],">="&$A14,QualliCalls[Quali-Call am],"<"&EDATE($A14,1),QualliCalls[Quali-Ergebnis],"Qualifiziert") -> 0 | G14: =IFERROR(F14/E14,"") | H14: =COUNTIFS(SaleCalls[Closing-Call am],">="&$A14,SaleCalls[Closing-Call am],"<"&EDATE($A14,1)) -> 0 | I14: =COUNTIFS(SaleCalls[Closing-Call am],">="&$A14,SaleCalls[Closing-Call am],"<"&EDATE($A14,1),SaleCalls[Sales-Ergebnis],"Abgeschlossen") -> 0 | J14: =IFERROR(I14/H14,"")
A15: =DATE($F$2,12,1) -> 46357 | B15: =COUNTIFS(Akquise[Erstkontakt am],">="&$A15,Akquise[Erstkontakt am],"<"&EDATE($A15,1)) -> 0 | C15: =COUNTIFS(Akquise[Erstkontakt am],">="&$A15,Akquise[Erstkontakt am],"<"&EDATE($A15,1),Akquise[Akquise-Ergebnis],"Qualifiziert") -> 0 | D15: =IFERROR(C15/B15,"") | E15: =COUNTIFS(QualliCalls[Quali-Call am],">="&$A15,QualliCalls[Quali-Call am],"<"&EDATE($A15,1)) -> 0 | F15: =COUNTIFS(QualliCalls[Quali-Call am],">="&$A15,QualliCalls[Quali-Call am],"<"&EDATE($A15,1),QualliCalls[Quali-Ergebnis],"Qualifiziert") -> 0 | G15: =IFERROR(F15/E15,"") | H15: =COUNTIFS(SaleCalls[Closing-Call am],">="&$A15,SaleCalls[Closing-Call am],"<"&EDATE($A15,1)) -> 0 | I15: =COUNTIFS(SaleCalls[Closing-Call am],">="&$A15,SaleCalls[Closing-Call am],"<"&EDATE($A15,1),SaleCalls[Sales-Ergebnis],"Abgeschlossen") -> 0 | J15: =IFERROR(I15/H15,"")
A16: ⌀ Durchschnitt | B16: =SUM(B4:B15) -> 2 | C16: =SUM(C4:C15) -> 2 | D16: =IFERROR(C16/B16,"") -> 1 | E16: =SUM(E4:E15) -> 2 | F16: =SUM(F4:F15) -> 2 | G16: =IFERROR(F16/E16,"") -> 1 | H16: =SUM(H4:H15) -> 1 | I16: =SUM(I4:I15) -> 1 | J16: =IFERROR(I16/H16,"") -> 1
A18: Diese Quoten lesen die Datums- und Ergebnis-Spalten der Phasen-Blätter (Akquise / Quali-Calls / Sales-Calls) monatlich aus. Sie füllen sich automatisch, sobald du dort Calls mit Datum + Ergebnis einträgst. Die ⌀-Zeile speist die „Zielplanung".

Sheet Umsatz
B1: [Schuck] Webdesign · Umsatz 2026
D2: Auswertungsjahr: | F2: 2026
B3: Monat | C3: Abschlüsse Neukunden | D3: Abschlüsse Bestandskunden | E3: Auftragsvolumen Neukunden (€) | F3: Auftragsvolumen Bestandskunden (€) | G3: Cashflow Gesamt (€)
B4: =DATE($F$2,1,1) -> 46023 | C4: =COUNTIFS(Kunden[Abschluss am],">="&$B4,Kunden[Abschluss am],"<"&EDATE($B4,1)) -> 0 | E4: =SUMIFS(Kunden[Auftragsvolumen (€)],Kunden[Abschluss am],">="&$B4,Kunden[Abschluss am],"<"&EDATE($B4,1)) -> 0
B5: =DATE($F$2,2,1) -> 46054 | C5: =COUNTIFS(Kunden[Abschluss am],">="&$B5,Kunden[Abschluss am],"<"&EDATE($B5,1)) -> 0 | E5: =SUMIFS(Kunden[Auftragsvolumen (€)],Kunden[Abschluss am],">="&$B5,Kunden[Abschluss am],"<"&EDATE($B5,1)) -> 0
B6: =DATE($F$2,3,1) -> 46082 | C6: =COUNTIFS(Kunden[Abschluss am],">="&$B6,Kunden[Abschluss am],"<"&EDATE($B6,1)) -> 0 | E6: =SUMIFS(Kunden[Auftragsvolumen (€)],Kunden[Abschluss am],">="&$B6,Kunden[Abschluss am],"<"&EDATE($B6,1)) -> 0
B7: =DATE($F$2,4,1) -> 46113 | C7: =COUNTIFS(Kunden[Abschluss am],">="&$B7,Kunden[Abschluss am],"<"&EDATE($B7,1)) -> 0 | E7: =SUMIFS(Kunden[Auftragsvolumen (€)],Kunden[Abschluss am],">="&$B7,Kunden[Abschluss am],"<"&EDATE($B7,1)) -> 0
B8: =DATE($F$2,5,1) -> 46143 | C8: =COUNTIFS(Kunden[Abschluss am],">="&$B8,Kunden[Abschluss am],"<"&EDATE($B8,1)) -> 0 | E8: =SUMIFS(Kunden[Auftragsvolumen (€)],Kunden[Abschluss am],">="&$B8,Kunden[Abschluss am],"<"&EDATE($B8,1)) -> 0
B9: =DATE($F$2,6,1) -> 46174 | C9: =COUNTIFS(Kunden[Abschluss am],">="&$B9,Kunden[Abschluss am],"<"&EDATE($B9,1)) -> 1 | E9: =SUMIFS(Kunden[Auftragsvolumen (€)],Kunden[Abschluss am],">="&$B9,Kunden[Abschluss am],"<"&EDATE($B9,1)) -> 1300
B10: =DATE($F$2,7,1) -> 46204 | C10: =COUNTIFS(Kunden[Abschluss am],">="&$B10,Kunden[Abschluss am],"<"&EDATE($B10,1)) -> 0 | E10: =SUMIFS(Kunden[Auftragsvolumen (€)],Kunden[Abschluss am],">="&$B10,Kunden[Abschluss am],"<"&EDATE($B10,1)) -> 0
B11: =DATE($F$2,8,1) -> 46235 | C11: =COUNTIFS(Kunden[Abschluss am],">="&$B11,Kunden[Abschluss am],"<"&EDATE($B11,1)) -> 0 | E11: =SUMIFS(Kunden[Auftragsvolumen (€)],Kunden[Abschluss am],">="&$B11,Kunden[Abschluss am],"<"&EDATE($B11,1)) -> 0
B12: =DATE($F$2,9,1) -> 46266 | C12: =COUNTIFS(Kunden[Abschluss am],">="&$B12,Kunden[Abschluss am],"<"&EDATE($B12,1)) -> 0 | E12: =SUMIFS(Kunden[Auftragsvolumen (€)],Kunden[Abschluss am],">="&$B12,Kunden[Abschluss am],"<"&EDATE($B12,1)) -> 0
B13: =DATE($F$2,10,1) -> 46296 | C13: =COUNTIFS(Kunden[Abschluss am],">="&$B13,Kunden[Abschluss am],"<"&EDATE($B13,1)) -> 0 | E13: =SUMIFS(Kunden[Auftragsvolumen (€)],Kunden[Abschluss am],">="&$B13,Kunden[Abschluss am],"<"&EDATE($B13,1)) -> 0
B14: =DATE($F$2,11,1) -> 46327 | C14: =COUNTIFS(Kunden[Abschluss am],">="&$B14,Kunden[Abschluss am],"<"&EDATE($B14,1)) -> 0 | E14: =SUMIFS(Kunden[Auftragsvolumen (€)],Kunden[Abschluss am],">="&$B14,Kunden[Abschluss am],"<"&EDATE($B14,1)) -> 0
B15: =DATE($F$2,12,1) -> 46357 | C15: =COUNTIFS(Kunden[Abschluss am],">="&$B15,Kunden[Abschluss am],"<"&EDATE($B15,1)) -> 0 | E15: =SUMIFS(Kunden[Auftragsvolumen (€)],Kunden[Abschluss am],">="&$B15,Kunden[Abschluss am],"<"&EDATE($B15,1)) -> 0
B16: Gesamt | C16: =SUM(C4:C15) -> 1 | D16: =SUM(D4:D15) -> 0 | E16: =SUM(E4:E15) -> 1300 | F16: =SUM(F4:F15) -> 0 | G16: =SUM(G4:G15) -> 0
B18: Erklärung der Felder:
B19: • Abschlüsse / Auftragsvolumen Neukunden — ziehen sich automatisch aus „Kunden" nach Abschluss-Monat.
B20: • Abschlüsse / Auftragsvolumen Bestandskunden — manuell (Upsells, Care-/SEO-Erweiterungen).
B21: • Cashflow Gesamt (€) — tatsächlicher Zahlungseingang im Monat (manuell).

Sheet Zielplanung
B1: [Schuck] Webdesign · Zielplanung (Reverse Funnel)
B3: ANNAHMEN (anpassbar) | E3: LIVE-QUOTEN (aus Funnel & Quoten)
B4: Zusätzlicher Zielumsatz / Monat (€) | C4: 10000 | E4: Akquise-Quote (⌀) | F4: ='Funnel & Quoten'!D16 -> 1
B5: ⌀ Auftragswert pro Kunde (€) | C5: 5000 | E5: Quali-Quote (⌀) | F5: ='Funnel & Quoten'!G16 -> 1
B6: Abschlussquote (Sales → Kunde) | C6: 0.4 | E6: Abschluss-Quote (⌀) | F6: ='Funnel & Quoten'!J16 -> 1
B7: Quali-Quote (Quali → Sales) | C7: 0.5
B8: Akquise-Quote (Erstkontakt → Quali) | C8: 0.25 | E8: Trage erst deine Schätzwerte (gelb) ein. Sobald echte Calls in den Phasen-Blättern stehen, vergleiche mit den Live-Quoten und justiere nach.
B9: Zeithorizont (Wochen) | C9: 8
B11: BENÖTIGTE AKTIVITÄT
B12: Benötigte Abschlüsse (Kunden) | C12: =CEILING(C4/C5,1) -> 2
B13: Benötigte Sales-Calls | C13: =CEILING(C12/C6,1) -> 5
B14: Benötigte Quali-Calls | C14: =CEILING(C13/C7,1) -> 10
B15: Benötigte Erstkontakte | C15: =CEILING(C14/C8,1) -> 40
B17: Erstkontakte pro Woche | C17: =CEILING(C15/C9,1) -> 5
B18: Erstkontakte pro Werktag | C18: =CEILING(C15/C9/5,1) -> 1
B20: Gelb = anpassbar · Blau = berechnet

Sheet Listen
A1: Zielgruppe | B1: Quelle | C1: Website-Qualität | D1: Priorität | E1: Akquise-Ergebnis | F1: Quali-Ergebnis | G1: Sales-Ergebnis
A2: Coaches & Berater | B2: KI | C2: Sehr schlecht | D2: 🔴 Hoch | E2: Offen | F2: Offen | G2: Offen
A3: Steuerberater & Anwälte | B3: Google | C3: Schlecht | D3: 🟡 Mittel | E3: Nicht erreicht | F3: Follow-up | G3: Follow-up
A4: Immobilien & Makler | B4: LinkedIn | C4: Ausbaufähig | D4: 🟢 Niedrig | E4: Wiedervorlage | F4: Disqualifiziert | G4: Abgelehnt
A5: Handwerk & Lokal | B5: Empfehlung | C5: OK | E5: Kein Interesse | F5: Qualifiziert | G5: Abgeschlossen
A6: Musik & Event | B6: Kaltakquise | C6: Gut | E6: Qualifiziert
A7: Agentur (Subcontracting) | B7: Messe | C7: Keine Website
A8: Sonstige | B8: DATEV
B9: Anwaltskammer
B10: Website
B11: Netzwerk
